[2025-06-04T06:09:33.287+0000] {taskinstance.py:1956} INFO - Dependencies all met for dep_context=non-requeueable deps ti=<TaskInstance: auto_pull_dags_from_github.git_pull_latest_dags manual__2025-06-04T06:08:24.473784+00:00 [queued]>
[2025-06-04T06:09:33.295+0000] {taskinstance.py:1956} INFO - Dependencies all met for dep_context=requeueable deps ti=<TaskInstance: auto_pull_dags_from_github.git_pull_latest_dags manual__2025-06-04T06:08:24.473784+00:00 [queued]>
[2025-06-04T06:09:33.295+0000] {taskinstance.py:2170} INFO - Starting attempt 2 of 3
[2025-06-04T06:09:33.304+0000] {taskinstance.py:2191} INFO - Executing <Task(BashOperator): git_pull_latest_dags> on 2025-06-04 06:08:24.473784+00:00
[2025-06-04T06:09:33.309+0000] {standard_task_runner.py:60} INFO - Started process 196 to run task
[2025-06-04T06:09:33.314+0000] {standard_task_runner.py:87} INFO - Running: ['***', 'tasks', 'run', 'auto_pull_dags_from_github', 'git_pull_latest_dags', 'manual__2025-06-04T06:08:24.473784+00:00', '--job-id', '33', '--raw', '--subdir', 'DAGS_FOLDER/auto_pull_dags.py', '--cfg-path', '/tmp/tmp1rejwywp']
[2025-06-04T06:09:33.316+0000] {standard_task_runner.py:88} INFO - Job 33: Subtask git_pull_latest_dags
[2025-06-04T06:09:33.378+0000] {task_command.py:423} INFO - Running <TaskInstance: auto_pull_dags_from_github.git_pull_latest_dags manual__2025-06-04T06:08:24.473784+00:00 [running]> on host 76ddeb3967d1
[2025-06-04T06:09:33.433+0000] {taskinstance.py:2480} INFO - Exporting env vars: AIRFLOW_CTX_DAG_EMAIL='aswin.b@sganlytics.com' AIRFLOW_CTX_DAG_OWNER='***' AIRFLOW_CTX_DAG_ID='auto_pull_dags_from_github' AIRFLOW_CTX_TASK_ID='git_pull_latest_dags' AIRFLOW_CTX_EXECUTION_DATE='2025-06-04T06:08:24.473784+00:00' AIRFLOW_CTX_TRY_NUMBER='2' AIRFLOW_CTX_DAG_RUN_ID='manual__2025-06-04T06:08:24.473784+00:00'
[2025-06-04T06:09:33.435+0000] {subprocess.py:63} INFO - Tmp dir root location: /tmp
[2025-06-04T06:09:33.436+0000] {subprocess.py:75} INFO - Running command: ['/usr/bin/bash', '-c', 'cd /opt/***/dags && git pull origin main']
[2025-06-04T06:09:33.443+0000] {subprocess.py:86} INFO - Output:
[2025-06-04T06:09:33.445+0000] {subprocess.py:93} INFO - /usr/bin/bash: line 1: git: command not found
[2025-06-04T06:09:33.446+0000] {subprocess.py:97} INFO - Command exited with return code 127
[2025-06-04T06:09:33.455+0000] {taskinstance.py:2698} ERROR - Task failed with exception
Traceback (most recent call last):
  File "/home/airflow/.local/lib/python3.8/site-packages/airflow/models/taskinstance.py", line 433, in _execute_task
    result = execute_callable(context=context, **execute_callable_kwargs)
  File "/home/airflow/.local/lib/python3.8/site-packages/airflow/operators/bash.py", line 212, in execute
    raise AirflowException(
airflow.exceptions.AirflowException: Bash command failed. The command returned a non-zero exit code 127.
[2025-06-04T06:09:33.457+0000] {taskinstance.py:1138} INFO - Marking task as UP_FOR_RETRY. dag_id=auto_pull_dags_from_github, task_id=git_pull_latest_dags, execution_date=20250604T060824, start_date=20250604T060933, end_date=20250604T060933
[2025-06-04T06:09:33.466+0000] {standard_task_runner.py:107} ERROR - Failed to execute job 33 for task git_pull_latest_dags (Bash command failed. The command returned a non-zero exit code 127.; 196)
[2025-06-04T06:09:33.485+0000] {local_task_job_runner.py:234} INFO - Task exited with return code 1
[2025-06-04T06:09:33.499+0000] {taskinstance.py:3280} INFO - 0 downstream tasks scheduled from follow-on schedule check
