[2025-06-04T15:22:39.586+0000] {taskinstance.py:1956} INFO - Dependencies all met for dep_context=non-requeueable deps ti=<TaskInstance: demo_etl_pipeline.transform manual__2025-06-04T15:22:36.470152+00:00 [queued]>
[2025-06-04T15:22:39.596+0000] {taskinstance.py:1956} INFO - Dependencies all met for dep_context=requeueable deps ti=<TaskInstance: demo_etl_pipeline.transform manual__2025-06-04T15:22:36.470152+00:00 [queued]>
[2025-06-04T15:22:39.601+0000] {taskinstance.py:2170} INFO - Starting attempt 1 of 2
[2025-06-04T15:22:39.618+0000] {taskinstance.py:2191} INFO - Executing <Task(PythonOperator): transform> on 2025-06-04 15:22:36.470152+00:00
[2025-06-04T15:22:39.623+0000] {standard_task_runner.py:60} INFO - Started process 7044 to run task
[2025-06-04T15:22:39.626+0000] {standard_task_runner.py:87} INFO - Running: ['***', 'tasks', 'run', 'demo_etl_pipeline', 'transform', 'manual__2025-06-04T15:22:36.470152+00:00', '--job-id', '56', '--raw', '--subdir', 'DAGS_FOLDER/sample_etl_dag.py', '--cfg-path', '/tmp/tmpuw4ke2ck']
[2025-06-04T15:22:39.629+0000] {standard_task_runner.py:88} INFO - Job 56: Subtask transform
[2025-06-04T15:22:39.701+0000] {task_command.py:423} INFO - Running <TaskInstance: demo_etl_pipeline.transform manual__2025-06-04T15:22:36.470152+00:00 [running]> on host 036d21481f2d
[2025-06-04T15:22:39.763+0000] {taskinstance.py:2480} INFO - Exporting env vars: AIRFLOW_CTX_DAG_EMAIL='aswin.b@sganlytics.com' AIRFLOW_CTX_DAG_OWNER='***' AIRFLOW_CTX_DAG_ID='demo_etl_pipeline' AIRFLOW_CTX_TASK_ID='transform' AIRFLOW_CTX_EXECUTION_DATE='2025-06-04T15:22:36.470152+00:00' AIRFLOW_CTX_TRY_NUMBER='1' AIRFLOW_CTX_DAG_RUN_ID='manual__2025-06-04T15:22:36.470152+00:00'
[2025-06-04T15:22:39.765+0000] {logging_mixin.py:188} INFO - ⚠️ Simulating failure in transform step
[2025-06-04T15:22:39.766+0000] {taskinstance.py:2698} ERROR - Task failed with exception
Traceback (most recent call last):
  File "/home/airflow/.local/lib/python3.8/site-packages/airflow/models/taskinstance.py", line 433, in _execute_task
    result = execute_callable(context=context, **execute_callable_kwargs)
  File "/home/airflow/.local/lib/python3.8/site-packages/airflow/operators/python.py", line 199, in execute
    return_value = self.execute_callable()
  File "/home/airflow/.local/lib/python3.8/site-packages/airflow/operators/python.py", line 216, in execute_callable
    return self.python_callable(*self.op_args, **self.op_kwargs)
  File "/opt/airflow/dags/sample_etl_dag.py", line 21, in transform
    raise Exception("Simulated failure for demo purposes")
Exception: Simulated failure for demo purposes
[2025-06-04T15:22:39.780+0000] {taskinstance.py:1138} INFO - Marking task as UP_FOR_RETRY. dag_id=demo_etl_pipeline, task_id=transform, execution_date=20250604T152236, start_date=20250604T152239, end_date=20250604T152239
[2025-06-04T15:22:39.791+0000] {standard_task_runner.py:107} ERROR - Failed to execute job 56 for task transform (Simulated failure for demo purposes; 7044)
[2025-06-04T15:22:39.802+0000] {local_task_job_runner.py:234} INFO - Task exited with return code 1
[2025-06-04T15:22:39.822+0000] {taskinstance.py:3280} INFO - 0 downstream tasks scheduled from follow-on schedule check
