[2025-06-04T06:02:03.224+0000] {taskinstance.py:1956} INFO - Dependencies all met for dep_context=non-requeueable deps ti=<TaskInstance: auto_pull_dags_from_github.git_pull_latest_dags scheduled__2025-06-04T05:00:00+00:00 [queued]>
[2025-06-04T06:02:03.230+0000] {taskinstance.py:1956} INFO - Dependencies all met for dep_context=requeueable deps ti=<TaskInstance: auto_pull_dags_from_github.git_pull_latest_dags scheduled__2025-06-04T05:00:00+00:00 [queued]>
[2025-06-04T06:02:03.230+0000] {taskinstance.py:2170} INFO - Starting attempt 2 of 2
[2025-06-04T06:02:03.239+0000] {taskinstance.py:2191} INFO - Executing <Task(BashOperator): git_pull_latest_dags> on 2025-06-04 05:00:00+00:00
[2025-06-04T06:02:03.245+0000] {standard_task_runner.py:60} INFO - Started process 76 to run task
[2025-06-04T06:02:03.248+0000] {standard_task_runner.py:87} INFO - Running: ['***', 'tasks', 'run', 'auto_pull_dags_from_github', 'git_pull_latest_dags', 'scheduled__2025-06-04T05:00:00+00:00', '--job-id', '31', '--raw', '--subdir', 'DAGS_FOLDER/auto_pull_dags.py', '--cfg-path', '/tmp/tmp1qg9pu3i']
[2025-06-04T06:02:03.251+0000] {standard_task_runner.py:88} INFO - Job 31: Subtask git_pull_latest_dags
[2025-06-04T06:02:03.317+0000] {task_command.py:423} INFO - Running <TaskInstance: auto_pull_dags_from_github.git_pull_latest_dags scheduled__2025-06-04T05:00:00+00:00 [running]> on host 76ddeb3967d1
[2025-06-04T06:02:03.371+0000] {taskinstance.py:2480} INFO - Exporting env vars: AIRFLOW_CTX_DAG_EMAIL='aswin.b@sganlytics.com' AIRFLOW_CTX_DAG_OWNER='***' AIRFLOW_CTX_DAG_ID='auto_pull_dags_from_github' AIRFLOW_CTX_TASK_ID='git_pull_latest_dags' AIRFLOW_CTX_EXECUTION_DATE='2025-06-04T05:00:00+00:00' AIRFLOW_CTX_TRY_NUMBER='2' AIRFLOW_CTX_DAG_RUN_ID='scheduled__2025-06-04T05:00:00+00:00'
[2025-06-04T06:02:03.373+0000] {subprocess.py:63} INFO - Tmp dir root location: /tmp
[2025-06-04T06:02:03.374+0000] {subprocess.py:75} INFO - Running command: ['/usr/bin/bash', '-c', 'cd /opt/***/dags && git pull origin main']
[2025-06-04T06:02:03.383+0000] {subprocess.py:86} INFO - Output:
[2025-06-04T06:02:03.386+0000] {subprocess.py:93} INFO - /usr/bin/bash: line 1: git: command not found
[2025-06-04T06:02:03.387+0000] {subprocess.py:97} INFO - Command exited with return code 127
[2025-06-04T06:02:03.395+0000] {taskinstance.py:2698} ERROR - Task failed with exception
Traceback (most recent call last):
  File "/home/airflow/.local/lib/python3.8/site-packages/airflow/models/taskinstance.py", line 433, in _execute_task
    result = execute_callable(context=context, **execute_callable_kwargs)
  File "/home/airflow/.local/lib/python3.8/site-packages/airflow/operators/bash.py", line 212, in execute
    raise AirflowException(
airflow.exceptions.AirflowException: Bash command failed. The command returned a non-zero exit code 127.
[2025-06-04T06:02:03.398+0000] {taskinstance.py:1138} INFO - Marking task as FAILED. dag_id=auto_pull_dags_from_github, task_id=git_pull_latest_dags, execution_date=20250604T050000, start_date=20250604T060203, end_date=20250604T060203
[2025-06-04T06:02:03.411+0000] {warnings.py:109} WARNING - /home/***/.local/lib/python3.8/site-packages/***/utils/email.py:154: RemovedInAirflow3Warning: Fetching SMTP credentials from configuration variables will be deprecated in a future release. Please set credentials using a connection instead.
  send_mime_email(e_from=mail_from, e_to=recipients, mime_msg=msg, conn_id=conn_id, dryrun=dryrun)

[2025-06-04T06:02:03.411+0000] {configuration.py:1046} WARNING - section/key [smtp/smtp_user] not found in config
[2025-06-04T06:02:03.412+0000] {email.py:270} INFO - Email alerting: attempt 1
[2025-06-04T06:02:03.418+0000] {configuration.py:1046} WARNING - section/key [smtp/smtp_user] not found in config
[2025-06-04T06:02:03.418+0000] {email.py:270} INFO - Email alerting: attempt 1
[2025-06-04T06:02:03.419+0000] {taskinstance.py:826} ERROR - Failed to send email to: ['aswin.b@sganlytics.com']
Traceback (most recent call last):
  File "/home/airflow/.local/lib/python3.8/site-packages/airflow/models/taskinstance.py", line 2334, in _run_raw_task
    self._execute_task_with_callbacks(context, test_mode, session=session)
  File "/home/airflow/.local/lib/python3.8/site-packages/airflow/models/taskinstance.py", line 2499, in _execute_task_with_callbacks
    result = self._execute_task(context, task_orig)
  File "/home/airflow/.local/lib/python3.8/site-packages/airflow/models/taskinstance.py", line 2516, in _execute_task
    return _execute_task(self, context, task_orig)
  File "/home/airflow/.local/lib/python3.8/site-packages/airflow/models/taskinstance.py", line 433, in _execute_task
    result = execute_callable(context=context, **execute_callable_kwargs)
  File "/home/airflow/.local/lib/python3.8/site-packages/airflow/operators/bash.py", line 212, in execute
    raise AirflowException(
airflow.exceptions.AirflowException: Bash command failed. The command returned a non-zero exit code 127.

During handling of the above exception, another exception occurred:

Traceback (most recent call last):
  File "/home/airflow/.local/lib/python3.8/site-packages/airflow/models/taskinstance.py", line 1000, in _email_alert
    send_email(task.email, subject, html_content)
  File "/home/airflow/.local/lib/python3.8/site-packages/airflow/utils/email.py", line 80, in send_email
    return backend(
  File "/home/airflow/.local/lib/python3.8/site-packages/airflow/utils/email.py", line 154, in send_email_smtp
    send_mime_email(e_from=mail_from, e_to=recipients, mime_msg=msg, conn_id=conn_id, dryrun=dryrun)
  File "/home/airflow/.local/lib/python3.8/site-packages/airflow/utils/email.py", line 272, in send_mime_email
    smtp_conn = _get_smtp_connection(smtp_host, smtp_port, smtp_timeout, smtp_ssl)
  File "/home/airflow/.local/lib/python3.8/site-packages/airflow/utils/email.py", line 316, in _get_smtp_connection
    return smtplib.SMTP(host=host, port=port, timeout=timeout)
  File "/usr/local/lib/python3.8/smtplib.py", line 255, in __init__
    (code, msg) = self.connect(host, port)
  File "/usr/local/lib/python3.8/smtplib.py", line 339, in connect
    self.sock = self._get_socket(host, port, self.timeout)
  File "/usr/local/lib/python3.8/smtplib.py", line 310, in _get_socket
    return socket.create_connection((host, port), timeout,
  File "/usr/local/lib/python3.8/socket.py", line 808, in create_connection
    raise err
  File "/usr/local/lib/python3.8/socket.py", line 796, in create_connection
    sock.connect(sa)
ConnectionRefusedError: [Errno 111] Connection refused

During handling of the above exception, another exception occurred:

Traceback (most recent call last):
  File "/home/airflow/.local/lib/python3.8/site-packages/airflow/models/taskinstance.py", line 824, in _handle_failure
    task_instance.email_alert(error, failure_context["task"])
  File "/home/airflow/.local/lib/python3.8/site-packages/airflow/models/taskinstance.py", line 2946, in email_alert
    _email_alert(task_instance=self, exception=exception, task=task)
  File "/home/airflow/.local/lib/python3.8/site-packages/airflow/models/taskinstance.py", line 1002, in _email_alert
    send_email(task.email, subject, html_content_err)
  File "/home/airflow/.local/lib/python3.8/site-packages/airflow/utils/email.py", line 80, in send_email
    return backend(
  File "/home/airflow/.local/lib/python3.8/site-packages/airflow/utils/email.py", line 154, in send_email_smtp
    send_mime_email(e_from=mail_from, e_to=recipients, mime_msg=msg, conn_id=conn_id, dryrun=dryrun)
  File "/home/airflow/.local/lib/python3.8/site-packages/airflow/utils/email.py", line 272, in send_mime_email
    smtp_conn = _get_smtp_connection(smtp_host, smtp_port, smtp_timeout, smtp_ssl)
  File "/home/airflow/.local/lib/python3.8/site-packages/airflow/utils/email.py", line 316, in _get_smtp_connection
    return smtplib.SMTP(host=host, port=port, timeout=timeout)
  File "/usr/local/lib/python3.8/smtplib.py", line 255, in __init__
    (code, msg) = self.connect(host, port)
  File "/usr/local/lib/python3.8/smtplib.py", line 339, in connect
    self.sock = self._get_socket(host, port, self.timeout)
  File "/usr/local/lib/python3.8/smtplib.py", line 310, in _get_socket
    return socket.create_connection((host, port), timeout,
  File "/usr/local/lib/python3.8/socket.py", line 808, in create_connection
    raise err
  File "/usr/local/lib/python3.8/socket.py", line 796, in create_connection
    sock.connect(sa)
ConnectionRefusedError: [Errno 111] Connection refused
[2025-06-04T06:02:03.431+0000] {standard_task_runner.py:107} ERROR - Failed to execute job 31 for task git_pull_latest_dags (Bash command failed. The command returned a non-zero exit code 127.; 76)
[2025-06-04T06:02:03.465+0000] {local_task_job_runner.py:234} INFO - Task exited with return code 1
[2025-06-04T06:02:03.483+0000] {taskinstance.py:3280} INFO - 0 downstream tasks scheduled from follow-on schedule check
