[2025-06-04T05:52:57.488+0000] {taskinstance.py:1956} INFO - Dependencies all met for dep_context=non-requeueable deps ti=<TaskInstance: auto_pull_dags_from_github.git_pull_latest_dags manual__2025-06-04T05:50:53.895939+00:00 [queued]>
[2025-06-04T05:52:57.497+0000] {taskinstance.py:1956} INFO - Dependencies all met for dep_context=requeueable deps ti=<TaskInstance: auto_pull_dags_from_github.git_pull_latest_dags manual__2025-06-04T05:50:53.895939+00:00 [queued]>
[2025-06-04T05:52:57.498+0000] {taskinstance.py:2170} INFO - Starting attempt 2 of 2
[2025-06-04T05:52:57.510+0000] {taskinstance.py:2191} INFO - Executing <Task(BashOperator): git_pull_latest_dags> on 2025-06-04 05:50:53.895939+00:00
[2025-06-04T05:52:57.515+0000] {standard_task_runner.py:60} INFO - Started process 87 to run task
[2025-06-04T05:52:57.518+0000] {standard_task_runner.py:87} INFO - Running: ['***', 'tasks', 'run', 'auto_pull_dags_from_github', 'git_pull_latest_dags', 'manual__2025-06-04T05:50:53.895939+00:00', '--job-id', '16', '--raw', '--subdir', 'DAGS_FOLDER/auto_pull_dags.py', '--cfg-path', '/tmp/tmpnnh627bo']
[2025-06-04T05:52:57.521+0000] {standard_task_runner.py:88} INFO - Job 16: Subtask git_pull_latest_dags
[2025-06-04T05:52:57.612+0000] {task_command.py:423} INFO - Running <TaskInstance: auto_pull_dags_from_github.git_pull_latest_dags manual__2025-06-04T05:50:53.895939+00:00 [running]> on host 76ddeb3967d1
[2025-06-04T05:52:57.696+0000] {taskinstance.py:2480} INFO - Exporting env vars: AIRFLOW_CTX_DAG_OWNER='***' AIRFLOW_CTX_DAG_ID='auto_pull_dags_from_github' AIRFLOW_CTX_TASK_ID='git_pull_latest_dags' AIRFLOW_CTX_EXECUTION_DATE='2025-06-04T05:50:53.895939+00:00' AIRFLOW_CTX_TRY_NUMBER='2' AIRFLOW_CTX_DAG_RUN_ID='manual__2025-06-04T05:50:53.895939+00:00'
[2025-06-04T05:52:57.699+0000] {subprocess.py:63} INFO - Tmp dir root location: /tmp
[2025-06-04T05:52:57.701+0000] {subprocess.py:75} INFO - Running command: ['/usr/bin/bash', '-c', 'cd /opt/***/dags && git pull origin main']
[2025-06-04T05:52:57.716+0000] {subprocess.py:86} INFO - Output:
[2025-06-04T05:52:57.719+0000] {subprocess.py:93} INFO - /usr/bin/bash: line 1: git: command not found
[2025-06-04T05:52:57.721+0000] {subprocess.py:97} INFO - Command exited with return code 127
[2025-06-04T05:52:57.735+0000] {taskinstance.py:2698} ERROR - Task failed with exception
Traceback (most recent call last):
  File "/home/airflow/.local/lib/python3.8/site-packages/airflow/models/taskinstance.py", line 433, in _execute_task
    result = execute_callable(context=context, **execute_callable_kwargs)
  File "/home/airflow/.local/lib/python3.8/site-packages/airflow/operators/bash.py", line 212, in execute
    raise AirflowException(
airflow.exceptions.AirflowException: Bash command failed. The command returned a non-zero exit code 127.
[2025-06-04T05:52:57.742+0000] {taskinstance.py:1138} INFO - Marking task as FAILED. dag_id=auto_pull_dags_from_github, task_id=git_pull_latest_dags, execution_date=20250604T055053, start_date=20250604T055257, end_date=20250604T055257
[2025-06-04T05:52:57.759+0000] {standard_task_runner.py:107} ERROR - Failed to execute job 16 for task git_pull_latest_dags (Bash command failed. The command returned a non-zero exit code 127.; 87)
[2025-06-04T05:52:57.812+0000] {local_task_job_runner.py:234} INFO - Task exited with return code 1
[2025-06-04T05:52:57.833+0000] {taskinstance.py:3280} INFO - 0 downstream tasks scheduled from follow-on schedule check
