[2025-06-04T05:50:55.792+0000] {taskinstance.py:1956} INFO - Dependencies all met for dep_context=non-requeueable deps ti=<TaskInstance: auto_pull_dags_from_github.git_pull_latest_dags manual__2025-06-04T05:50:53.895939+00:00 [queued]>
[2025-06-04T05:50:55.802+0000] {taskinstance.py:1956} INFO - Dependencies all met for dep_context=requeueable deps ti=<TaskInstance: auto_pull_dags_from_github.git_pull_latest_dags manual__2025-06-04T05:50:53.895939+00:00 [queued]>
[2025-06-04T05:50:55.803+0000] {taskinstance.py:2170} INFO - Starting attempt 1 of 2
[2025-06-04T05:50:55.816+0000] {taskinstance.py:2191} INFO - Executing <Task(BashOperator): git_pull_latest_dags> on 2025-06-04 05:50:53.895939+00:00
[2025-06-04T05:50:55.821+0000] {standard_task_runner.py:60} INFO - Started process 1044 to run task
[2025-06-04T05:50:55.825+0000] {standard_task_runner.py:87} INFO - Running: ['***', 'tasks', 'run', 'auto_pull_dags_from_github', 'git_pull_latest_dags', 'manual__2025-06-04T05:50:53.895939+00:00', '--job-id', '12', '--raw', '--subdir', 'DAGS_FOLDER/auto_pull_dags.py', '--cfg-path', '/tmp/tmpgkegeacp']
[2025-06-04T05:50:55.829+0000] {standard_task_runner.py:88} INFO - Job 12: Subtask git_pull_latest_dags
[2025-06-04T05:50:55.911+0000] {task_command.py:423} INFO - Running <TaskInstance: auto_pull_dags_from_github.git_pull_latest_dags manual__2025-06-04T05:50:53.895939+00:00 [running]> on host 76ddeb3967d1
[2025-06-04T05:50:55.982+0000] {taskinstance.py:2480} INFO - Exporting env vars: AIRFLOW_CTX_DAG_OWNER='***' AIRFLOW_CTX_DAG_ID='auto_pull_dags_from_github' AIRFLOW_CTX_TASK_ID='git_pull_latest_dags' AIRFLOW_CTX_EXECUTION_DATE='2025-06-04T05:50:53.895939+00:00' AIRFLOW_CTX_TRY_NUMBER='1' AIRFLOW_CTX_DAG_RUN_ID='manual__2025-06-04T05:50:53.895939+00:00'
[2025-06-04T05:50:55.985+0000] {subprocess.py:63} INFO - Tmp dir root location: /tmp
[2025-06-04T05:50:55.986+0000] {subprocess.py:75} INFO - Running command: ['/usr/bin/bash', '-c', 'cd /opt/***/dags && git pull origin main']
[2025-06-04T05:50:55.996+0000] {subprocess.py:86} INFO - Output:
[2025-06-04T05:50:55.998+0000] {subprocess.py:93} INFO - /usr/bin/bash: line 1: git: command not found
[2025-06-04T05:50:55.999+0000] {subprocess.py:97} INFO - Command exited with return code 127
[2025-06-04T05:50:56.011+0000] {taskinstance.py:2698} ERROR - Task failed with exception
Traceback (most recent call last):
  File "/home/airflow/.local/lib/python3.8/site-packages/airflow/models/taskinstance.py", line 433, in _execute_task
    result = execute_callable(context=context, **execute_callable_kwargs)
  File "/home/airflow/.local/lib/python3.8/site-packages/airflow/operators/bash.py", line 212, in execute
    raise AirflowException(
airflow.exceptions.AirflowException: Bash command failed. The command returned a non-zero exit code 127.
[2025-06-04T05:50:56.014+0000] {taskinstance.py:1138} INFO - Marking task as UP_FOR_RETRY. dag_id=auto_pull_dags_from_github, task_id=git_pull_latest_dags, execution_date=20250604T055053, start_date=20250604T055055, end_date=20250604T055056
[2025-06-04T05:50:56.024+0000] {standard_task_runner.py:107} ERROR - Failed to execute job 12 for task git_pull_latest_dags (Bash command failed. The command returned a non-zero exit code 127.; 1044)
[2025-06-04T05:50:56.039+0000] {local_task_job_runner.py:234} INFO - Task exited with return code 1
[2025-06-04T05:50:56.060+0000] {taskinstance.py:3280} INFO - 0 downstream tasks scheduled from follow-on schedule check
