[2025-06-04T05:52:53.702+0000] {taskinstance.py:1956} INFO - Dependencies all met for dep_context=non-requeueable deps ti=<TaskInstance: auto_pull_dags_from_github.git_pull_latest_dags scheduled__2025-06-04T04:00:00+00:00 [queued]>
[2025-06-04T05:52:53.713+0000] {taskinstance.py:1956} INFO - Dependencies all met for dep_context=requeueable deps ti=<TaskInstance: auto_pull_dags_from_github.git_pull_latest_dags scheduled__2025-06-04T04:00:00+00:00 [queued]>
[2025-06-04T05:52:53.714+0000] {taskinstance.py:2170} INFO - Starting attempt 2 of 2
[2025-06-04T05:52:53.727+0000] {taskinstance.py:2191} INFO - Executing <Task(BashOperator): git_pull_latest_dags> on 2025-06-04 04:00:00+00:00
[2025-06-04T05:52:53.734+0000] {standard_task_runner.py:60} INFO - Started process 75 to run task
[2025-06-04T05:52:53.739+0000] {standard_task_runner.py:87} INFO - Running: ['***', 'tasks', 'run', 'auto_pull_dags_from_github', 'git_pull_latest_dags', 'scheduled__2025-06-04T04:00:00+00:00', '--job-id', '15', '--raw', '--subdir', 'DAGS_FOLDER/auto_pull_dags.py', '--cfg-path', '/tmp/tmpxhi5q98t']
[2025-06-04T05:52:53.744+0000] {standard_task_runner.py:88} INFO - Job 15: Subtask git_pull_latest_dags
[2025-06-04T05:52:53.830+0000] {task_command.py:423} INFO - Running <TaskInstance: auto_pull_dags_from_github.git_pull_latest_dags scheduled__2025-06-04T04:00:00+00:00 [running]> on host 76ddeb3967d1
[2025-06-04T05:52:53.918+0000] {taskinstance.py:2480} INFO - Exporting env vars: AIRFLOW_CTX_DAG_OWNER='***' AIRFLOW_CTX_DAG_ID='auto_pull_dags_from_github' AIRFLOW_CTX_TASK_ID='git_pull_latest_dags' AIRFLOW_CTX_EXECUTION_DATE='2025-06-04T04:00:00+00:00' AIRFLOW_CTX_TRY_NUMBER='2' AIRFLOW_CTX_DAG_RUN_ID='scheduled__2025-06-04T04:00:00+00:00'
[2025-06-04T05:52:53.921+0000] {subprocess.py:63} INFO - Tmp dir root location: /tmp
[2025-06-04T05:52:53.922+0000] {subprocess.py:75} INFO - Running command: ['/usr/bin/bash', '-c', 'cd /opt/***/dags && git pull origin main']
[2025-06-04T05:52:53.934+0000] {subprocess.py:86} INFO - Output:
[2025-06-04T05:52:53.937+0000] {subprocess.py:93} INFO - /usr/bin/bash: line 1: git: command not found
[2025-06-04T05:52:53.938+0000] {subprocess.py:97} INFO - Command exited with return code 127
[2025-06-04T05:52:53.954+0000] {taskinstance.py:2698} ERROR - Task failed with exception
Traceback (most recent call last):
  File "/home/airflow/.local/lib/python3.8/site-packages/airflow/models/taskinstance.py", line 433, in _execute_task
    result = execute_callable(context=context, **execute_callable_kwargs)
  File "/home/airflow/.local/lib/python3.8/site-packages/airflow/operators/bash.py", line 212, in execute
    raise AirflowException(
airflow.exceptions.AirflowException: Bash command failed. The command returned a non-zero exit code 127.
[2025-06-04T05:52:53.959+0000] {taskinstance.py:1138} INFO - Marking task as FAILED. dag_id=auto_pull_dags_from_github, task_id=git_pull_latest_dags, execution_date=20250604T040000, start_date=20250604T055253, end_date=20250604T055253
[2025-06-04T05:52:53.976+0000] {standard_task_runner.py:107} ERROR - Failed to execute job 15 for task git_pull_latest_dags (Bash command failed. The command returned a non-zero exit code 127.; 75)
[2025-06-04T05:52:53.991+0000] {local_task_job_runner.py:234} INFO - Task exited with return code 1
[2025-06-04T05:52:54.010+0000] {taskinstance.py:3280} INFO - 0 downstream tasks scheduled from follow-on schedule check
