[2025-06-04T05:57:17.546+0000] {taskinstance.py:1956} INFO - Dependencies all met for dep_context=non-requeueable deps ti=<TaskInstance: demo_etl_pipeline.transform manual__2025-06-04T05:57:14.280193+00:00 [queued]>
[2025-06-04T05:57:17.552+0000] {taskinstance.py:1956} INFO - Dependencies all met for dep_context=requeueable deps ti=<TaskInstance: demo_etl_pipeline.transform manual__2025-06-04T05:57:14.280193+00:00 [queued]>
[2025-06-04T05:57:17.559+0000] {taskinstance.py:2170} INFO - Starting attempt 1 of 2
[2025-06-04T05:57:17.571+0000] {taskinstance.py:2191} INFO - Executing <Task(PythonOperator): transform> on 2025-06-04 05:57:14.280193+00:00
[2025-06-04T05:57:17.576+0000] {standard_task_runner.py:60} INFO - Started process 179 to run task
[2025-06-04T05:57:17.579+0000] {standard_task_runner.py:87} INFO - Running: ['***', 'tasks', 'run', 'demo_etl_pipeline', 'transform', 'manual__2025-06-04T05:57:14.280193+00:00', '--job-id', '25', '--raw', '--subdir', 'DAGS_FOLDER/sample_etl_dag.py', '--cfg-path', '/tmp/tmpgxab3_0h']
[2025-06-04T05:57:17.582+0000] {standard_task_runner.py:88} INFO - Job 25: Subtask transform
[2025-06-04T05:57:17.638+0000] {task_command.py:423} INFO - Running <TaskInstance: demo_etl_pipeline.transform manual__2025-06-04T05:57:14.280193+00:00 [running]> on host 76ddeb3967d1
[2025-06-04T05:57:17.686+0000] {taskinstance.py:2480} INFO - Exporting env vars: AIRFLOW_CTX_DAG_EMAIL='aswin.b@sganlytics.com' AIRFLOW_CTX_DAG_OWNER='***' AIRFLOW_CTX_DAG_ID='demo_etl_pipeline' AIRFLOW_CTX_TASK_ID='transform' AIRFLOW_CTX_EXECUTION_DATE='2025-06-04T05:57:14.280193+00:00' AIRFLOW_CTX_TRY_NUMBER='1' AIRFLOW_CTX_DAG_RUN_ID='manual__2025-06-04T05:57:14.280193+00:00'
[2025-06-04T05:57:17.688+0000] {logging_mixin.py:188} INFO - ⚠️ Simulating failure in transform step
[2025-06-04T05:57:17.688+0000] {taskinstance.py:2698} ERROR - Task failed with exception
Traceback (most recent call last):
  File "/home/airflow/.local/lib/python3.8/site-packages/airflow/models/taskinstance.py", line 433, in _execute_task
    result = execute_callable(context=context, **execute_callable_kwargs)
  File "/home/airflow/.local/lib/python3.8/site-packages/airflow/operators/python.py", line 199, in execute
    return_value = self.execute_callable()
  File "/home/airflow/.local/lib/python3.8/site-packages/airflow/operators/python.py", line 216, in execute_callable
    return self.python_callable(*self.op_args, **self.op_kwargs)
  File "/opt/airflow/dags/sample_etl_dag.py", line 21, in transform
    raise Exception("Simulated failure for demo purposes")
Exception: Simulated failure for demo purposes
[2025-06-04T05:57:17.699+0000] {taskinstance.py:1138} INFO - Marking task as UP_FOR_RETRY. dag_id=demo_etl_pipeline, task_id=transform, execution_date=20250604T055714, start_date=20250604T055717, end_date=20250604T055717
[2025-06-04T05:57:17.706+0000] {standard_task_runner.py:107} ERROR - Failed to execute job 25 for task transform (Simulated failure for demo purposes; 179)
[2025-06-04T05:57:17.715+0000] {local_task_job_runner.py:234} INFO - Task exited with return code 1
[2025-06-04T05:57:17.732+0000] {taskinstance.py:3280} INFO - 0 downstream tasks scheduled from follow-on schedule check
